Workbook
Name japan: 'BIS + EDBA Final'!$D$116

Sheet Filtered G500
B1: Company | C1: HQ | D1: Industry | E1: Employees | F1: Emp Count | G1: MSK RISK | H1: BIS | I1: EDBA | J1: CBG | K1: Total Score | L1: Revenues ($M) | M1: Rev % Change | N1: Profits ($M) | O1: Profits % Change | P1: Assets ($M) | Q1: Change in Rank | R1: Years on Global 500 List
B2: United Parcel Service | C2: United States | D2: Logistics | E2: 372180 | F2: {=_xlfn.IFS( E2<=$E$245,0, E2<=$E$246,1, E2<=$E$247,2, E2>=$E$247,3)} -> 3 | G2: {=_xlfn.IFS( OR(D2="Aerospace",D2="Aerospace & Defense",D2="Agricultural Equipment",D2="Airlines",D2="Automotive",D2="Automotive & Energy",D2="Automotive Components",D2="Aviation",D2="Building Materials",D2="Chemicals",D2="Commercial Vehicles",D2="Conglomerate & Defense",D2="Conglomerate & Energy",D2="Construction",D2="Construction & Infrastructure",D2="Construction & Real Estate",D2="Construction & Telecom",D2="Discount Retail",D2="Energy Management",D2="Energy Technology",D2="Engines & Power Systems",D2="Environmental Services",D2="Food Distribution",D2="Food Services",D2="Grocery Retail",D2="Healthcare & Pharmacy",D2="Home Improvement Retail",D2="Industrial Engineering & Electronics",D2="Oilfield Services",D2="Pharmaceuticals",D2="Pharmaceuticals & Chemicals",D2="Pharmaceuticals & Healthcare",D2="Pharmacy Retail",D2="Postal & Logistics",D2="Retail",D2="Retail & Distribution",D2="Retail & Grocery",D2="Retail (IKEA)",D2="Tobacco",D2="Trading & Conglomerate",D2="Utilities",D2="Utilities & Energy",D2="Wholesale Retail"),2, OR(D2="Agribusiness",D2="Automotive & Heavy Vehicles",D2="Chemicals",D2="Commercial Vehicles",D2="Construction",D2="Construction & Infrastructure",D2="Engines & Power Systems",D2="Food Processing",D2="Healthcare",D2="Healthcare & Medical Devices",D2="Heavy Equipment",D2="Heavy Industry",D2="Industrial Gases",D2="Industrial Manufacturing",D2="Logistics",D2="Medical Devices",D2="Mining",D2="Mining & Commodities Trading",D2="Oil & Gas",D2="Oilfield Services",D2="Rail Transport",D2="Shipping & Logistics",D2="Steel"),3, OR(D2="Apparel & Footwear",D2="Beverage",D2="Coffeehouse & Retail",D2="Conglomerate",D2="Consumer Goods",D2="Convenience Retail",D2="Electronics",D2="Electronics & Semiconductors",D2="Electronics Retail",D2="Fashion Retail",D2="Food & Beverage",D2="Food Retail & Consumer Goods",D2="Industrial & Technology",D2="Industrial Automation",D2="Industrial Technology",D2="Postal & Financial Services",D2="Postal Services",D2="Scientific Instruments",D2="Technology Hardware",D2="Trading Company",D2="IT Consulting"),1, OR(D2="Cosmetics",D2="E-commerce & Cloud Computing",D2="Electronics & Entertainment",D2="Entertainment & Media",D2="Luxury Goods",D2="Media & Telecommunications",D2="Networking Technology",D2="Real Estate Services",D2="Technology & Consumer Electronics",D2="Telecommunications",D2="Telecommunications & Investment"),1, OR(D2="Asset Management",D2="Banking",D2="Banking & Asset Services",D2="Banking & Financial Services",D2="Banking & Wealth Management",D2="Cloud Software",D2="Enterprise Software",D2="Financial Services",D2="Information Technology Consulting",D2="Investment Banking",D2="Social Media & Technology",D2="Software & Cloud Computing",D2="Technology & Consulting",D2="Technology & Internet Services",D2="Technology & Software"),1, TRUE,"Unmapped" )} -> 3 | H2: =VLOOKUP(B2,'BIS + EDBA Final'!A:K,2,FALSE) -> 1 | I2: =VLOOKUP(B2,'BIS + EDBA Final'!A:F,6,FALSE) -> 1 | J2: =VLOOKUP(B2,'CBG Final'!A:B,2,FALSE) -> 3 | K2: =0.3*F2+0.2*G2+0.2*H2+I2*0.1+J2*0.2 -> 2.4 | L2: 91,070 | M2: 0.1% | N2: 5,782 | O2: -13.8% | P2: 70,070 | Q2: 1 | R2: 31
B3: FedEx | C3: United States | D3: Logistics | E3: 494824 | F3: {=_xlfn.IFS( E3<=$E$245,0, E3<=$E$246,1, E3<=$E$247,2, E3>=$E$247,3)} -> 3 | G3: {=_xlfn.IFS( OR(D3="Aerospace",D3="Aerospace & Defense",D3="Agricultural Equipment",D3="Airlines",D3="Automotive",D3="Automotive & Energy",D3="Automotive Components",D3="Aviation",D3="Building Materials",D3="Chemicals",D3="Commercial Vehicles",D3="Conglomerate & Defense",D3="Conglomerate & Energy",D3="Construction",D3="Construction & Infrastructure",D3="Construction & Real Estate",D3="Construction & Telecom",D3="Discount Retail",D3="Energy Management",D3="Energy Technology",D3="Engines & Power Systems",D3="Environmental Services",D3="Food Distribution",D3="Food Services",D3="Grocery Retail",D3="Healthcare & Pharmacy",D3="Home Improvement Retail",D3="Industrial Engineering & Electronics",D3="Oilfield Services",D3="Pharmaceuticals",D3="Pharmaceuticals & Chemicals",D3="Pharmaceuticals & Healthcare",D3="Pharmacy Retail",D3="Postal & Logistics",D3="Retail",D3="Retail & Distribution",D3="Retail & Grocery",D3="Retail (IKEA)",D3="Tobacco",D3="Trading & Conglomerate",D3="Utilities",D3="Utilities & Energy",D3="Wholesale Retail"),2, OR(D3="Agribusiness",D3="Automotive & Heavy Vehicles",D3="Chemicals",D3="Commercial Vehicles",D3="Construction",D3="Construction & Infrastructure",D3="Engines & Power Systems",D3="Food Processing",D3="Healthcare",D3="Healthcare & Medical Devices",D3="Heavy Equipment",D3="Heavy Industry",D3="Industrial Gases",D3="Industrial Manufacturing",D3="Logistics",D3="Medical Devices",D3="Mining",D3="Mining & Commodities Trading",D3="Oil & Gas",D3="Oilfield Services",D3="Rail Transport",D3="Shipping & Logistics",D3="Steel"),3, OR(D3="Apparel & Footwear",D3="Beverage",D3="Coffeehouse & Retail",D3="Conglomerate",D3="Consumer Goods",D3="Convenience Retail",D3="Electronics",D3="Electronics & Semiconductors",D3="Electronics Retail",D3="Fashion Retail",D3="Food & Beverage",D3="Food Retail & Consumer Goods",D3="Industrial & Technology",D3="Industrial Automation",D3="Industrial Technology",D3="Postal & Financial Services",D3="Postal Services",D3="Scientific Instruments",D3="Technology Hardware",D3="Trading Company",D3="IT Consulting"),1, OR(D3="Cosmetics",D3="E-commerce & Cloud Computing",D3="Electronics & Entertainment",D3="Entertainment & Media",D3="Luxury Goods",D3="Media & Telecommunications",D3="Networking Technology",D3="Real Estate Services",D3="Technology & Consumer Electronics",D3="Telecommunications",D3="Telecommunications & Investment"),1, OR(D3="Asset Management",D3="Banking",D3="Banking & Asset Services",D3="Banking & Financial Services",D3="Banking & Wealth Management",D3="Cloud Software",D3="Enterprise Software",D3="Financial Services",D3="Information Technology Consulting",D3="Investment Banking",D3="Social Media & Technology",D3="Software & Cloud Computing",D3="Technology & Consulting",D3="Technology & Internet Services",D3="Technology & Software"),1, TRUE,"Unmapped" )} -> 3 | H3: =VLOOKUP(B3,'BIS + EDBA Final'!A:K,2,FALSE) -> 1 | I3: =VLOOKUP(B3,'BIS + EDBA Final'!A:F,6,FALSE) -> 1 | J3: =VLOOKUP(B3,'CBG Final'!A:B,2,FALSE) -> 3 | K3: =0.3*F3+0.2*G3+0.2*H3+I3*0.1+J3*0.2 -> 2.4 | L3: 87,693 | M3: -2.7% | N3: 4,331 | O3: 9% | P3: 87,007 | Q3: -8 | R3: 31
B4: Tesco | C4: United Kingdom | D4: Retail | E4: 229140 | F4: {=_xlfn.IFS( E4<=$E$245,0, E4<=$E$246,1, E4<=$E$247,2, E4>=$E$247,3)} -> 3 | G4: {=_xlfn.IFS( OR(D4="Aerospace",D4="Aerospace & Defense",D4="Agricultural Equipment",D4="Airlines",D4="Automotive",D4="Automotive & Energy",D4="Automotive Components",D4="Aviation",D4="Building Materials",D4="Chemicals",D4="Commercial Vehicles",D4="Conglomerate & Defense",D4="Conglomerate & Energy",D4="Construction",D4="Construction & Infrastructure",D4="Construction & Real Estate",D4="Construction & Telecom",D4="Discount Retail",D4="Energy Management",D4="Energy Technology",D4="Engines & Power Systems",D4="Environmental Services",D4="Food Distribution",D4="Food Services",D4="Grocery Retail",D4="Healthcare & Pharmacy",D4="Home Improvement Retail",D4="Industrial Engineering & Electronics",D4="Oilfield Services",D4="Pharmaceuticals",D4="Pharmaceuticals & Chemicals",D4="Pharmaceuticals & Healthcare",D4="Pharmacy Retail",D4="Postal & Logistics",D4="Retail",D4="Retail & Distribution",D4="Retail & Grocery",D4="Retail (IKEA)",D4="Tobacco",D4="Trading & Conglomerate",D4="Utilities",D4="Utilities & Energy",D4="Wholesale Retail"),2, OR(D4="Agribusiness",D4="Automotive & Heavy Vehicles",D4="Chemicals",D4="Commercial Vehicles",D4="Construction",D4="Construction & Infrastructure",D4="Engines & Power Systems",D4="Food Processing",D4="Healthcare",D4="Healthcare & Medical Devices",D4="Heavy Equipment",D4="Heavy Industry",D4="Industrial Gases",D4="Industrial Manufacturing",D4="Logistics",D4="Medical Devices",D4="Mining",D4="Mining & Commodities Trading",D4="Oil & Gas",D4="Oilfield Services",D4="Rail Transport",D4="Shipping & Logistics",D4="Steel"),3, OR(D4="Apparel & Footwear",D4="Beverage",D4="Coffeehouse & Retail",D4="Conglomerate",D4="Consumer Goods",D4="Convenience Retail",D4="Electronics",D4="Electronics & Semiconductors",D4="Electronics Retail",D4="Fashion Retail",D4="Food & Beverage",D4="Food Retail & Consumer Goods",D4="Industrial & Technology",D4="Industrial Automation",D4="Industrial Technology",D4="Postal & Financial Services",D4="Postal Services",D4="Scientific Instruments",D4="Technology Hardware",D4="Trading Company",D4="IT Consulting"),1, OR(D4="Cosmetics",D4="E-commerce & Cloud Computing",D4="Electronics & Entertainment",D4="Entertainment & Media",D4="Luxury Goods",D4="Media & Telecommunications",D4="Networking Technology",D4="Real Estate Services",D4="Technology & Consumer Electronics",D4="Telecommunications",D4="Telecommunications & Investment"),1, OR(D4="Asset Management",D4="Banking",D4="Banking & Asset Services",D4="Banking & Financial Services",D4="Banking & Wealth Management",D4="Cloud Software",D4="Enterprise Software",D4="Financial Services",D4="Information Technology Consulting",D4="Investment Banking",D4="Social Media & Technology",D4="Software & Cloud Computing",D4="Technology & Consulting",D4="Technology & Internet Services",D4="Technology & Software"),1, TRUE,"Unmapped" )} -> 2 | H4: =VLOOKUP(B4,'BIS + EDBA Final'!A:K,2,FALSE) -> 2 | I4: =VLOOKUP(B4,'BIS + EDBA Final'!A:F,6,FALSE) -> 1 | J4: =VLOOKUP(B4,'CBG Final'!A:B,2,FALSE) -> 3 | K4: =0.3*F4+0.2*G4+0.2*H4+I4*0.1+J4*0.2 -> 2.4 | L4: 89,745.6 | M4: 4.1% | N4: 2,071 | O4: 39.3% | P4: 48,961.4 | Q4: 11 | R4: 31
B5: Walgreens Boots Alliance | C5: United States | D5: Pharmacy Retail | E5: 252500 | F5: {=_xlfn.IFS( E5<=$E$245,0, E5<=$E$246,1, E5<=$E$247,2, E5>=$E$247,3)} -> 3 | G5: {=_xlfn.IFS( OR(D5="Aerospace",D5="Aerospace & Defense",D5="Agricultural Equipment",D5="Airlines",D5="Automotive",D5="Automotive & Energy",D5="Automotive Components",D5="Aviation",D5="Building Materials",D5="Chemicals",D5="Commercial Vehicles",D5="Conglomerate & Defense",D5="Conglomerate & Energy",D5="Construction",D5="Construction & Infrastructure",D5="Construction & Real Estate",D5="Construction & Telecom",D5="Discount Retail",D5="Energy Management",D5="Energy Technology",D5="Engines & Power Systems",D5="Environmental Services",D5="Food Distribution",D5="Food Services",D5="Grocery Retail",D5="Healthcare & Pharmacy",D5="Home Improvement Retail",D5="Industrial Engineering & Electronics",D5="Oilfield Services",D5="Pharmaceuticals",D5="Pharmaceuticals & Chemicals",D5="Pharmaceuticals & Healthcare",D5="Pharmacy Retail",D5="Postal & Logistics",D5="Retail",D5="Retail & Distribution",D5="Retail & Grocery",D5="Retail (IKEA)",D5="Tobacco",D5="Trading & Conglomerate",D5="Utilities",D5="Utilities & Energy",D5="Wholesale Retail"),2, OR(D5="Agribusiness",D5="Automotive & Heavy Vehicles",D5="Chemicals",D5="Commercial Vehicles",D5="Construction",D5="Construction & Infrastructure",D5="Engines & Power Systems",D5="Food Processing",D5="Healthcare",D5="Healthcare & Medical Devices",D5="Heavy Equipment",D5="Heavy Industry",D5="Industrial Gases",D5="Industrial Manufacturing",D5="Logistics",D5="Medical Devices",D5="Mining",D5="Mining & Commodities Trading",D5="Oil & Gas",D5="Oilfield Services",D5="Rail Transport",D5="Shipping & Logistics",D5="Steel"),3, OR(D5="Apparel & Footwear",D5="Beverage",D5="Coffeehouse & Retail",D5="Conglomerate",D5="Consumer Goods",D5="Convenience Retail",D5="Electronics",D5="Electronics & Semiconductors",D5="Electronics Retail",D5="Fashion Retail",D5="Food & Beverage",D5="Food Retail & Consumer Goods",D5="Industrial & Technology",D5="Industrial Automation",D5="Industrial Technology",D5="Postal & Financial Services",D5="Postal Services",D5="Scientific Instruments",D5="Technology Hardware",D5="Trading Company",D5="IT Consulting"),1, OR(D5="Cosmetics",D5="E-commerce & Cloud Computing",D5="Electronics & Entertainment",D5="Entertainment & Media",D5="Luxury Goods",D5="Media & Telecommunications",D5="Networking Technology",D5="Real Estate Services",D5="Technology & Consumer Electronics",D5="Telecommunications",D5="Telecommunications & Investment"),1, OR(D5="Asset Management",D5="Banking",D5="Banking & Asset Services",D5="Banking & Financial Services",D5="Banking & Wealth Management",D5="Cloud Software",D5="Enterprise Software",D5="Financial Services",D5="Information Technology Consulting",D5="Investment Banking",D5="Social Media & Technology",D5="Software & Cloud Computing",D5="Technology & Consulting",D5="Technology & Internet Services",D5="Technology & Software"),1, TRUE,"Unmapped" )} -> 2 | H5: 2 | I5: =VLOOKUP(B5,'BIS + EDBA Final'!A:F,6,FALSE) -> 1 | J5: =VLOOKUP(B5,'CBG Final'!A:B,2,FALSE) -> 3 | K5: =0.3*F5+0.2*G5+0.2*H5+I5*0.1+J5*0.2 -> 2.4 | L5: 147,658 | M5: 6.2% | N5: -8,636 | P5: 81,037 | Q5: 8 | R5: 31
B6: Abbott Laboratories | C6: United States | D6: Healthcare & Medical Devices | E6: 114000 | F6: {=_xlfn.IFS( E6<=$E$245,0, E6<=$E$246,1, E6<=$E$247,2, E6>=$E$247,3)} -> 2 | G6: {=_xlfn.IFS( OR(D6="Aerospace",D6="Aerospace & Defense",D6="Agricultural Equipment",D6="Airlines",D6="Automotive",D6="Automotive & Energy",D6="Automotive Components",D6="Aviation",D6="Building Materials",D6="Chemicals",D6="Commercial Vehicles",D6="Conglomerate & Defense",D6="Conglomerate & Energy",D6="Construction",D6="Construction & Infrastructure",D6="Construction & Real Estate",D6="Construction & Telecom",D6="Discount Retail",D6="Energy Management",D6="Energy Technology",D6="Engines & Power Systems",D6="Environmental Services",D6="Food Distribution",D6="Food Services",D6="Grocery Retail",D6="Healthcare & Pharmacy",D6="Home Improvement Retail",D6="Industrial Engineering & Electronics",D6="Oilfield Services",D6="Pharmaceuticals",D6="Pharmaceuticals & Chemicals",D6="Pharmaceuticals & Healthcare",D6="Pharmacy Retail",D6="Postal & Logistics",D6="Retail",D6="Retail & Distribution",D6="Retail & Grocery",D6="Retail (IKEA)",D6="Tobacco",D6="Trading & Conglomerate",D6="Utilities",D6="Utilities & Energy",D6="Wholesale Retail"),2, OR(D6="Agribusiness",D6="Automotive & Heavy Vehicles",D6="Chemicals",D6="Commercial Vehicles",D6="Construction",D6="Construction & Infrastructure",D6="Engines & Power Systems",D6="Food Processing",D6="Healthcare",D6="Healthcare & Medical Devices",D6="Heavy Equipment",D6="Heavy Industry",D6="Industrial Gases",D6="Industrial Manufacturing",D6="Logistics",D6="Medical Devices",D6="Mining",D6="Mining & Commodities Trading",D6="Oil & Gas",D6="Oilfield Services",D6="Rail Transport",D6="Shipping & Logistics",D6="Steel"),3, OR(D6="Apparel & Footwear",D6="Beverage",D6="Coffeehouse & Retail",D6="Conglomerate",D6="Consumer Goods",D6="Convenience Retail",D6="Electronics",D6="Electronics & Semiconductors",D6="Electronics Retail",D6="Fashion Retail",D6="Food & Beverage",D6="Food Retail & Consumer Goods",D6="Industrial & Technology",D6="Industrial Automation",D6="Industrial Technology",D6="Postal & Financial Services",D6="Postal Services",D6="Scientific Instruments",D6="Technology Hardware",D6="Trading Company",D6="IT Consulting"),1, OR(D6="Cosmetics",D6="E-commerce & Cloud Computing",D6="Electronics & Entertainment",D6="Entertainment & Media",D6="Luxury Goods",D6="Media & Telecommunications",D6="Networking Technology",D6="Real Estate Services",D6="Technology & Consumer Electronics",D6="Telecommunications",D6="Telecommunications & Investment"),1, OR(D6="Asset Management",D6="Banking",D6="Banking & Asset Services",D6="Banking & Financial Services",D6="Banking & Wealth Management",D6="Cloud Software",D6="Enterprise Software",D6="Financial Services",D6="Information Technology Consulting",D6="Investment Banking",D6="Social Media & Technology",D6="Software & Cloud Computing",D6="Technology & Consulting",D6="Technology & Internet Services",D6="Technology & Software"),1, TRUE,"Unmapped" )} -> 3 | H6: 2 | I6: =VLOOKUP(B6,'BIS + EDBA Final'!A:F,6,FALSE) -> 1 | J6: =VLOOKUP(B6,'CBG Final'!A:B,2,FALSE) -> 3 | K6: =0.3*F6+0.2*G6+0.2*H6+I6*0.1+J6*0.2 -> 2.3 | L6: 41,950 | M6: 4.6% | N6: 13,402 | O6: 134.2% | P6: 81,414 | Q6: 4 | R6: 27
B7: Caterpillar | C7: United States | D7: Heavy Equipment | E7: 112900 | F7: {=_xlfn.IFS( E7<=$E$245,0, E7<=$E$246,1, E7<=$E$247,2, E7>=$E$247,3)} -> 2 | G7: {=_xlfn.IFS( OR(D7="Aerospace",D7="Aerospace & Defense",D7="Agricultural Equipment",D7="Airlines",D7="Automotive",D7="Automotive & Energy",D7="Automotive Components",D7="Aviation",D7="Building Materials",D7="Chemicals",D7="Commercial Vehicles",D7="Conglomerate & Defense",D7="Conglomerate & Energy",D7="Construction",D7="Construction & Infrastructure",D7="Construction & Real Estate",D7="Construction & Telecom",D7="Discount Retail",D7="Energy Management",D7="Energy Technology",D7="Engines & Power Systems",D7="Environmental Services",D7="Food Distribution",D7="Food Services",D7="Grocery Retail",D7="Healthcare & Pharmacy",D7="Home Improvement Retail",D7="Industrial Engineering & Electronics",D7="Oilfield Services",D7="Pharmaceuticals",D7="Pharmaceuticals & Chemicals",D7="Pharmaceuticals & Healthcare",D7="Pharmacy Retail",D7="Postal & Logistics",D7="Retail",D7="Retail & Distribution",D7="Retail & Grocery",D7="Retail (IKEA)",D7="Tobacco",D7="Trading & Conglomerate",D7="Utilities",D7="Utilities & Energy",D7="Wholesale Retail"),2, OR(D7="Agribusiness",D7="Automotive & Heavy Vehicles",D7="Chemicals",D7="Commercial Vehicles",D7="Construction",D7="Construction & Infrastructure",D7="Engines & Power Systems",D7="Food Processing",D7="Healthcare",D7="Healthcare & Medical Devices",D7="Heavy Equipment",D7="Heavy Industry",D7="Industrial Gases",D7="Industrial Manufacturing",D7="Logistics",D7="Medical Devices",D7="Mining",D7="Mining & Commodities Trading",D7="Oil & Gas",D7="Oilfield Services",D7="Rail Transport",D7="Shipping & Logistics",D7="Steel"),3, OR(D7="Apparel & Footwear",D7="Beverage",D7="Coffeehouse & Retail",D7="Conglomerate",D7="Consumer Goods",D7="Convenience Retail",D7="Electronics",D7="Electronics & Semiconductors",D7="Electronics Retail",D7="Fashion Retail",D7="Food & Beverage",D7="Food Retail & Consumer Goods",D7="Industrial & Technology",D7="Industrial Automation",D7="Industrial Technology",D7="Postal & Financial Services",D7="Postal Services",D7="Scientific Instruments",D7="Technology Hardware",D7="Trading Company",D7="IT Consulting"),1, OR(D7="Cosmetics",D7="E-commerce & Cloud Computing",D7="Electronics & Entertainment",D7="Entertainment & Media",D7="Luxury Goods",D7="Media & Telecommunications",D7="Networking Technology",D7="Real Estate Services",D7="Technology & Consumer Electronics",D7="Telecommunications",D7="Telecommunications & Investment"),1, OR(D7="Asset Management",D7="Banking",D7="Banking & Asset Services",D7="Banking & Financial Services",D7="Banking & Wealth Management",D7="Cloud Software",D7="Enterprise Software",D7="Financial Services",D7="Information Technology Consulting",D7="Investment Banking",D7="Social Media & Technology",D7="Software & Cloud Computing",D7="Technology & Consulting",D7="Technology & Internet Services",D7="Technology & Software"),1, TRUE,"Unmapped" )} -> 3 | H7: 2 | I7: =VLOOKUP(B7,'BIS + EDBA Final'!A:F,6,FALSE) -> 1 | J7: =VLOOKUP(B7,'CBG Final'!A:B,2,FALSE) -> 3 | K7: =0.3*F7+0.2*G7+0.2*H7+I7*0.1+J7*0.2 -> 2.3 | L7: 64,809 | M7: -3.4% | N7: 10,792 | O7: 4.4% | P7: 87,764 | Q7: -14 | R7: 31
B8: Siemens | C8: Germany | D8: Industrial Manufacturing | E8: 327000 | F8: {=_xlfn.IFS( E8<=$E$245,0, E8<=$E$246,1, E8<=$E$247,2, E8>=$E$247,3)} -> 3 | G8: {=_xlfn.IFS( OR(D8="Aerospace",D8="Aerospace & Defense",D8="Agricultural Equipment",D8="Airlines",D8="Automotive",D8="Automotive & Energy",D8="Automotive Components",D8="Aviation",D8="Building Materials",D8="Chemicals",D8="Commercial Vehicles",D8="Conglomerate & Defense",D8="Conglomerate & Energy",D8="Construction",D8="Construction & Infrastructure",D8="Construction & Real Estate",D8="Construction & Telecom",D8="Discount Retail",D8="Energy Management",D8="Energy Technology",D8="Engines & Power Systems",D8="Environmental Services",D8="Food Distribution",D8="Food Services",D8="Grocery Retail",D8="Healthcare & Pharmacy",D8="Home Improvement Retail",D8="Industrial Engineering & Electronics",D8="Oilfield Services",D8="Pharmaceuticals",D8="Pharmaceuticals & Chemicals",D8="Pharmaceuticals & Healthcare",D8="Pharmacy Retail",D8="Postal & Logistics",D8="Retail",D8="Retail & Distribution",D8="Retail & Grocery",D8="Retail (IKEA)",D8="Tobacco",D8="Trading & Conglomerate",D8="Utilities",D8="Utilities & Energy",D8="Wholesale Retail"),2, OR(D8="Agribusiness",D8="Automotive & Heavy Vehicles",D8="Chemicals",D8="Commercial Vehicles",D8="Construction",D8="Construction & Infrastructure",D8="Engines & Power Systems",D8="Food Processing",D8="Healthcare",D8="Healthcare & Medical Devices",D8="Heavy Equipment",D8="Heavy Industry",D8="Industrial Gases",D8="Industrial Manufacturing",D8="Logistics",D8="Medical Devices",D8="Mining",D8="Mining & Commodities Trading",D8="Oil & Gas",D8="Oilfield Services",D8="Rail Transport",D8="Shipping & Logistics",D8="Steel"),3, OR(D8="Apparel & Footwear",D8="Beverage",D8="Coffeehouse & Retail",D8="Conglomerate",D8="Consumer Goods",D8="Convenience Retail",D8="Electronics",D8="Electronics & Semiconductors",D8="Electronics Retail",D8="Fashion Retail",D8="Food & Beverage",D8="Food Retail & Consumer Goods",D8="Industrial & Technology",D8="Industrial Automation",D8="Industrial Technology",D8="Postal & Financial Services",D8="Postal Services",D8="Scientific Instruments",D8="Technology Hardware",D8="Trading Company",D8="IT Consulting"),1, OR(D8="Cosmetics",D8="E-commerce & Cloud Computing",D8="Electronics & Entertainment",D8="Entertainment & Media",D8="Luxury Goods",D8="Media & Telecommunications",D8="Networking Technology",D8="Real Estate Services",D8="Technology & Consumer Electronics",D8="Telecommunications",D8="Telecommunications & Investment"),1, OR(D8="Asset Management",D8="Banking",D8="Banking & Asset Services",D8="Banking & Financial Services",D8="Banking & Wealth Management",D8="Cloud Software",D8="Enterprise Software",D8="Financial Services",D8="Information Technology Consulting",D8="Investment Banking",D8="Social Media & Technology",D8="Software & Cloud Computing",D8="Technology & Consulting",D8="Technology & Internet Services",D8="Technology & Software"),1, TRUE,"Unmapped" )} -> 3 | H8: =VLOOKUP(B8,'BIS + EDBA Final'!A:K,2,FALSE) -> 1 | I8: =VLOOKUP(B8,'BIS + EDBA Final'!A:F,6,FALSE) -> 0 | J8: =VLOOKUP(B8,'CBG Final'!A:B,2,FALSE) -> 3 | K8: =0.3*F8+0.2*G8+0.2*H8+I8*0.1+J8*0.2 -> 2.3 | L8: 85,432.8 | M8: 3% | N8: 8,998.5 | O8: 6.2% | P8: 164,729.7 | Q8: 1 | R8: 31
B9: DHL Group | C9: Germany | D9: Logistics | E9: 559051 | F9: {=_xlfn.IFS( E9<=$E$245,0, E9<=$E$246,1, E9<=$E$247,2, E9>=$E$247,3)} -> 3 | G9: {=_xlfn.IFS( OR(D9="Aerospace",D9="Aerospace & Defense",D9="Agricultural Equipment",D9="Airlines",D9="Automotive",D9="Automotive & Energy",D9="Automotive Components",D9="Aviation",D9="Building Materials",D9="Chemicals",D9="Commercial Vehicles",D9="Conglomerate & Defense",D9="Conglomerate & Energy",D9="Construction",D9="Construction & Infrastructure",D9="Construction & Real Estate",D9="Construction & Telecom",D9="Discount Retail",D9="Energy Management",D9="Energy Technology",D9="Engines & Power Systems",D9="Environmental Services",D9="Food Distribution",D9="Food Services",D9="Grocery Retail",D9="Healthcare & Pharmacy",D9="Home Improvement Retail",D9="Industrial Engineering & Electronics",D9="Oilfield Services",D9="Pharmaceuticals",D9="Pharmaceuticals & Chemicals",D9="Pharmaceuticals & Healthcare",D9="Pharmacy Retail",D9="Postal & Logistics",D9="Retail",D9="Retail & Distribution",D9="Retail & Grocery",D9="Retail (IKEA)",D9="Tobacco",D9="Trading & Conglomerate",D9="Utilities",D9="Utilities & Energy",D9="Wholesale Retail"),2, OR(D9="Agribusiness",D9="Automotive & Heavy Vehicles",D9="Chemicals",D9="Commercial Vehicles",D9="Construction",D9="Construction & Infrastructure",D9="Engines & Power Systems",D9="Food Processing",D9="Healthcare",D9="Healthcare & Medical Devices",D9="Heavy Equipment",D9="Heavy Industry",D9="Industrial Gases",D9="Industrial Manufacturing",D9="Logistics",D9="Medical Devices",D9="Mining",D9="Mining & Commodities Trading",D9="Oil & Gas",D9="Oilfield Services",D9="Rail Transport",D9="Shipping & Logistics",D9="Steel"),3, OR(D9="Apparel & Footwear",D9="Beverage",D9="Coffeehouse & Retail",D9="Conglomerate",D9="Consumer Goods",D9="Convenience Retail",D9="Electronics",D9="Electronics & Semiconductors",D9="Electronics Retail",D9="Fashion Retail",D9="Food & Beverage",D9="Food Retail & Consumer Goods",D9="Industrial & Technology",D9="Industrial Automation",D9="Industrial Technology",D9="Postal & Financial Services",D9="Postal Services",D9="Scientific Instruments",D9="Technology Hardware",D9="Trading Company",D9="IT Consulting"),1, OR(D9="Cosmetics",D9="E-commerce & Cloud Computing",D9="Electronics & Entertainment",D9="Entertainment & Media",D9="Luxury Goods",D9="Media & Telecommunications",D9="Networking Technology",D9="Real Estate Services",D9="Technology & Consumer Electronics",D9="Telecommunications",D9="Telecommunications & Investment"),1, OR(D9="Asset Management",D9="Banking",D9="Banking & Asset Services",D9="Banking & Financial Services",D9="Banking & Wealth Management",D9="Cloud Software",D9="Enterprise Software",D9="Financial Services",D9="Information Technology Consulting",D9="Investment Banking",D9="Social Media & Technology",D9="Software & Cloud Computing",D9="Technology & Consulting",D9="Technology & Internet Services",D9="Technology & Software"),1, TRUE,"Unmapped" )} -> 3 | H9: =VLOOKUP(B9,'BIS + EDBA Final'!A:K,2,FALSE) -> 2 | I9: =VLOOKUP(B9,'BIS + EDBA Final'!A:F,6,FALSE) -> 0 | J9: =VLOOKUP(B9,'CBG Final'!A:B,2,FALSE) -> 2 | K9: =0.3*F9+0.2*G9+0.2*H9+I9*0.1+J9*0.2 -> 2.3 | L9: 91,041.4 | M9: 3% | N9: 3,603.3 | O9: -9.4% | P9: 72,349.4 | Q9: 10 | R9: 31
B10: Deutsche Bahn | C10: Germany | D10: Rail Transport | E10: 296662 | F10: {=_xlfn.IFS( E10<=$E$245,0, E10<=$E$246,1, E10<=$E$247,2, E10>=$E$247,3)} -> 3 | G10: {=_xlfn.IFS( OR(D10="Aerospace",D10="Aerospace & Defense",D10="Agricultural Equipment",D10="Airlines",D10="Automotive",D10="Automotive & Energy",D10="Automotive Components",D10="Aviation",D10="Building Materials",D10="Chemicals",D10="Commercial Vehicles",D10="Conglomerate & Defense",D10="Conglomerate & Energy",D10="Construction",D10="Construction & Infrastructure",D10="Construction & Real Estate",D10="Construction & Telecom",D10="Discount Retail",D10="Energy Management",D10="Energy Technology",D10="Engines & Power Systems",D10="Environmental Services",D10="Food Distribution",D10="Food Services",D10="Grocery Retail",D10="Healthcare & Pharmacy",D10="Home Improvement Retail",D10="Industrial Engineering & Electronics",D10="Oilfield Services",D10="Pharmaceuticals",D10="Pharmaceuticals & Chemicals",D10="Pharmaceuticals & Healthcare",D10="Pharmacy Retail",D10="Postal & Logistics",D10="Retail",D10="Retail & Distribution",D10="Retail & Grocery",D10="Retail (IKEA)",D10="Tobacco",D10="Trading & Conglomerate",D10="Utilities",D10="Utilities & Energy",D10="Wholesale Retail"),2, OR(D10="Agribusiness",D10="Automotive & Heavy Vehicles",D10="Chemicals",D10="Commercial Vehicles",D10="Construction",D10="Construction & Infrastructure",D10="Engines & Power Systems",D10="Food Processing",D10="Healthcare",D10="Healthcare & Medical Devices",D10="Heavy Equipment",D10="Heavy Industry",D10="Industrial Gases",D10="Industrial Manufacturing",D10="Logistics",D10="Medical Devices",D10="Mining",D10="Mining & Commodities Trading",D10="Oil & Gas",D10="Oilfield Services",D10="Rail Transport",D10="Shipping & Logistics",D10="Steel"),3, OR(D10="Apparel & Footwear",D10="Beverage",D10="Coffeehouse & Retail",D10="Conglomerate",D10="Consumer Goods",D10="Convenience Retail",D10="Electronics",D10="Electronics & Semiconductors",D10="Electronics Retail",D10="Fashion Retail",D10="Food & Beverage",D10="Food Retail & Consumer Goods",D10="Industrial & Technology",D10="Industrial Automation",D10="Industrial Technology",D10="Postal & Financial Services",D10="Postal Services",D10="Scientific Instruments",D10="Technology Hardware",D10="Trading Company",D10="IT Consulting"),1, OR(D10="Cosmetics",D10="E-commerce & Cloud Computing",D10="Electronics & Entertainment",D10="Entertainment & Media",D10="Luxury Goods",D10="Media & Telecommunications",D10="Networking Technology",D10="Real Estate Services",D10="Technology & Consumer Electronics",D10="Telecommunications",D10="Telecommunications & Investment"),1, OR(D10="Asset Management",D10="Banking",D10="Banking & Asset Services",D10="Banking & Financial Services",D10="Banking & Wealth Management",D10="Cloud Software",D10="Enterprise Software",D10="Financial Services",D10="Information Technology Consulting",D10="Investment Banking",D10="Social Media & Technology",D10="Software & Cloud Computing",D10="Technology & Consulting",D10="Technology & Internet Services",D10="Technology & Software"),1, TRUE,"Unmapped" )} -> 3 | H10: =VLOOKUP(B10,'BIS + EDBA Final'!A:K,2,FALSE) -> 2 | I10: =VLOOKUP(B10,'BIS + EDBA Final'!A:F,6,FALSE) -> 0 | J10: =VLOOKUP(B10,'CBG Final'!A:B,2,FALSE) -> 2 | K10: =0.3*F10+0.2*G10+0.2*H10+I10*0.1+J10*0.2 -> 2.3 | L10: 50,972.2 | M10: -4.2% | N10: -844.6 | P10: 86,868.9 | Q10: -22 | R10: 31
B11: Accenture | C11: Ireland | D11: IT Consulting | E11: 774303 | F11: {=_xlfn.IFS( E11<=$E$245,0, E11<=$E$246,1, E11<=$E$247,2, E11>=$E$247,3)} -> 3 | G11: {=_xlfn.IFS( OR(D11="Aerospace",D11="Aerospace & Defense",D11="Agricultural Equipment",D11="Airlines",D11="Automotive",D11="Automotive & Energy",D11="Automotive Components",D11="Aviation",D11="Building Materials",D11="Chemicals",D11="Commercial Vehicles",D11="Conglomerate & Defense",D11="Conglomerate & Energy",D11="Construction",D11="Construction & Infrastructure",D11="Construction & Real Estate",D11="Construction & Telecom",D11="Discount Retail",D11="Energy Management",D11="Energy Technology",D11="Engines & Power Systems",D11="Environmental Services",D11="Food Distribution",D11="Food Services",D11="Grocery Retail",D11="Healthcare & Pharmacy",D11="Home Improvement Retail",D11="Industrial Engineering & Electronics",D11="Oilfield Services",D11="Pharmaceuticals",D11="Pharmaceuticals & Chemicals",D11="Pharmaceuticals & Healthcare",D11="Pharmacy Retail",D11="Postal & Logistics",D11="Retail",D11="Retail & Distribution",D11="Retail & Grocery",D11="Retail (IKEA)",D11="Tobacco",D11="Trading & Conglomerate",D11="Utilities",D11="Utilities & Energy",D11="Wholesale Retail"),2, OR(D11="Agribusiness",D11="Automotive & Heavy Vehicles",D11="Chemicals",D11="Commercial Vehicles",D11="Construction",D11="Construction & Infrastructure",D11="Engines & Power Systems",D11="Food Processing",D11="Healthcare",D11="Healthcare & Medical Devices",D11="Heavy Equipment",D11="Heavy Industry",D11="Industrial Gases",D11="Industrial Manufacturing",D11="Logistics",D11="Medical Devices",D11="Mining",D11="Mining & Commodities Trading",D11="Oil & Gas",D11="Oilfield Services",D11="Rail Transport",D11="Shipping & Logistics",D11="Steel"),3, OR(D11="Apparel & Footwear",D11="Beverage",D11="Coffeehouse & Retail",D11="Conglomerate",D11="Consumer Goods",D11="Convenience Retail",D11="Electronics",D11="Electronics & Semiconductors",D11="Electronics Retail",D11="Fashion Retail",D11="Food & Beverage",D11="Food Retail & Consumer Goods",D11="Industrial & Technology",D11="Industrial Automation",D11="Industrial Technology",D11="Postal & Financial Services",D11="Postal Services",D11="Scientific Instruments",D11="Technology Hardware",D11="Trading Company",D11="IT Consulting"),1, OR(D11="Cosmetics",D11="E-commerce & Cloud Computing",D11="Electronics & Entertainment",D11="Entertainment & Media",D11="Luxury Goods",D11="Media & Telecommunications",D11="Networking Technology",D11="Real Estate Services",D11="Technology & Consumer Electronics",D11="Telecommunications",D11="Telecommunications & Investment"),1, OR(D11="Asset Management",D11="Banking",D11="Banking & Asset Services",D11="Banking & Financial Services",D11="Banking & Wealth Management",D11="Cloud Software",D11="Enterprise Software",D11="Financial Services",D11="Information Technology Consulting",D11="Investment Banking",D11="Social Media & Technology",D11="Software & Cloud Computing",D11="Technology & Consulting",D11="Technology & Internet Services",D11="Technology & Software"),1, TRUE,"Unmapped" )} -> 1 | H11: 3 | I11: =VLOOKUP(B11,'BIS + EDBA Final'!A:F,6,FALSE) -> 0 | J11: =VLOOKUP(B11,'CBG Final'!A:B,2,FALSE) -> 3 | K11: =0.3*F11+0.2*G11+0.2*H11+I11*0.1+J11*0.2 -> 2.3 | L11: 64,896.5 | M11: 1.2% | N11: 7,264.8 | O11: 5.7% | P11: 55,932.4 | Q11: - | R11: 24
B12: CVS Health | C12: United States | D12: Healthcare & Pharmacy | E12: 259500 | F12: {=_xlfn.IFS( E12<=$E$245,0, E12<=$E$246,1, E12<=$E$247,2, E12>=$E$247,3)} -> 3 | G12: {=_xlfn.IFS( OR(D12="Aerospace",D12="Aerospace & Defense",D12="Agricultural Equipment",D12="Airlines",D12="Automotive",D12="Automotive & Energy",D12="Automotive Components",D12="Aviation",D12="Building Materials",D12="Chemicals",D12="Commercial Vehicles",D12="Conglomerate & Defense",D12="Conglomerate & Energy",D12="Construction",D12="Construction & Infrastructure",D12="Construction & Real Estate",D12="Construction & Telecom",D12="Discount Retail",D12="Energy Management",D12="Energy Technology",D12="Engines & Power Systems",D12="Environmental Services",D12="Food Distribution",D12="Food Services",D12="Grocery Retail",D12="Healthcare & Pharmacy",D12="Home Improvement Retail",D12="Industrial Engineering & Electronics",D12="Oilfield Services",D12="Pharmaceuticals",D12="Pharmaceuticals & Chemicals",D12="Pharmaceuticals & Healthcare",D12="Pharmacy Retail",D12="Postal & Logistics",D12="Retail",D12="Retail & Distribution",D12="Retail & Grocery",D12="Retail (IKEA)",D12="Tobacco",D12="Trading & Conglomerate",D12="Utilities",D12="Utilities & Energy",D12="Wholesale Retail"),2, OR(D12="Agribusiness",D12="Automotive & Heavy Vehicles",D12="Chemicals",D12="Commercial Vehicles",D12="Construction",D12="Construction & Infrastructure",D12="Engines & Power Systems",D12="Food Processing",D12="Healthcare",D12="Healthcare & Medical Devices",D12="Heavy Equipment",D12="Heavy Industry",D12="Industrial Gases",D12="Industrial Manufacturing",D12="Logistics",D12="Medical Devices",D12="Mining",D12="Mining & Commodities Trading",D12="Oil & Gas",D12="Oilfield Services",D12="Rail Transport",D12="Shipping & Logistics",D12="Steel"),3, OR(D12="Apparel & Footwear",D12="Beverage",D12="Coffeehouse & Retail",D12="Conglomerate",D12="Consumer Goods",D12="Convenience Retail",D12="Electronics",D12="Electronics & Semiconductors",D12="Electronics Retail",D12="Fashion Retail",D12="Food & Beverage",D12="Food Retail & Consumer Goods",D12="Industrial & Technology",D12="Industrial Automation",D12="Industrial Technology",D12="Postal & Financial Services",D12="Postal Services",D12="Scientific Instruments",D12="Technology Hardware",D12="Trading Company",D12="IT Consulting"),1, OR(D12="Cosmetics",D12="E-commerce & Cloud Computing",D12="Electronics & Entertainment",D12="Entertainment & Media",D12="Luxury Goods",D12="Media & Telecommunications",D12="Networking Technology",D12="Real Estate Services",D12="Technology & Consumer Electronics",D12="Telecommunications",D12="Telecommunications & Investment"),1, OR(D12="Asset Management",D12="Banking",D12="Banking & Asset Services",D12="Banking & Financial Services",D12="Banking & Wealth Management",D12="Cloud Software",D12="Enterprise Software",D12="Financial Services",D12="Information Technology Consulting",D12="Investment Banking",D12="Social Media & Technology",D12="Software & Cloud Computing",D12="Technology & Consulting",D12="Technology & Internet Services",D12="Technology & Software"),1, TRUE,"Unmapped" )} -> 2 | H12: 2 | I12: =VLOOKUP(B12,'BIS + EDBA Final'!A:F,6,FALSE) -> 0 | J12: =VLOOKUP(B12,'CBG Final'!A:B,2,FALSE) -> 3 | K12: =0.3*F12+0.2*G12+0.2*H12+I12*0.1+J12*0.2 -> 2.3 | L12: 372,809 | M12: 4.2% | N12: 4,614 | O12: -44.7% | P12: 253,215 | Q12: 1 | R12: 30
B13: Nestlé | C13: Switzerland | D13: Food & Beverage | E13: 277000 | F13: {=_xlfn.IFS( E13<=$E$245,0, E13<=$E$246,1, E13<=$E$247,2, E13>=$E$247,3)} -> 3 | G13: {=_xlfn.IFS( OR(D13="Aerospace",D13="Aerospace & Defense",D13="Agricultural Equipment",D13="Airlines",D13="Automotive",D13="Automotive & Energy",D13="Automotive Components",D13="Aviation",D13="Building Materials",D13="Chemicals",D13="Commercial Vehicles",D13="Conglomerate & Defense",D13="Conglomerate & Energy",D13="Construction",D13="Construction & Infrastructure",D13="Construction & Real Estate",D13="Construction & Telecom",D13="Discount Retail",D13="Energy Management",D13="Energy Technology",D13="Engines & Power Systems",D13="Environmental Services",D13="Food Distribution",D13="Food Services",D13="Grocery Retail",D13="Healthcare & Pharmacy",D13="Home Improvement Retail",D13="Industrial Engineering & Electronics",D13="Oilfield Services",D13="Pharmaceuticals",D13="Pharmaceuticals & Chemicals",D13="Pharmaceuticals & Healthcare",D13="Pharmacy Retail",D13="Postal & Logistics",D13="Retail",D13="Retail & Distribution",D13="Retail & Grocery",D13="Retail (IKEA)",D13="Tobacco",D13="Trading & Conglomerate",D13="Utilities",D13="Utilities & Energy",D13="Wholesale Retail"),2, OR(D13="Agribusiness",D13="Automotive & Heavy Vehicles",D13="Chemicals",D13="Commercial Vehicles",D13="Construction",D13="Construction & Infrastructure",D13="Engines & Power Systems",D13="Food Processing",D13="Healthcare",D13="Healthcare & Medical Devices",D13="Heavy Equipment",D13="Heavy Industry",D13="Industrial Gases",D13="Industrial Manufacturing",D13="Logistics",D13="Medical Devices",D13="Mining",D13="Mining & Commodities Trading",D13="Oil & Gas",D13="Oilfield Services",D13="Rail Transport",D13="Shipping & Logistics",D13="Steel"),3, OR(D13="Apparel & Footwear",D13="Beverage",D13="Coffeehouse & Retail",D13="Conglomerate",D13="Consumer Goods",D13="Convenience Retail",D13="Electronics",D13="Electronics & Semiconductors",D13="Electronics Retail",D13="Fashion Retail",D13="Food & Beverage",D13="Food Retail & Consumer Goods",D13="Industrial & Technology",D13="Industrial Automation",D13="Industrial Technology",D13="Postal & Financial Services",D13="Postal Services",D13="Scientific Instruments",D13="Technology Hardware",D13="Trading Company",D13="IT Consulting"),1, OR(D13="Cosmetics",D13="E-commerce & Cloud Computing",D13="Electronics & Entertainment",D13="Entertainment & Media",D13="Luxury Goods",D13="Media & Telecommunications",D13="Networking Technology",D13="Real Estate Services",D13="Technology & Consumer Electronics",D13="Telecommunications",D13="Telecommunications & Investment"),1, OR(D13="Asset Management",D13="Banking",D13="Banking & Asset Services",D13="Banking & Financial Services",D13="Banking & Wealth Management",D13="Cloud Software",D13="Enterprise Software",D13="Financial Services",D13="Information Technology Consulting",D13="Investment Banking",D13="Social Media & Technology",D13="Software & Cloud Computing",D13="Technology & Consulting",D13="Technology & Internet Services",D13="Technology & Software"),1, TRUE,"Unmapped" )} -> 1 | H13: =VLOOKUP(B13,'BIS + EDBA Final'!A:K,2,FALSE) -> 2 | I13: =VLOOKUP(B13,'BIS + EDBA Final'!A:F,6,FALSE) -> 1 | J13: =VLOOKUP(B13,'CBG Final'!A:B,2,FALSE) -> 3 | K13: =0.3*F13+0.2*G13+0.2*H13+I13*0.1+J13*0.2 -> 2.2 | L13: 103,749.5 | M13: 0.2% | N13: 12,360.8 | O13: -0.9% | P13: 153,713 | Q13: -1 | R13: 31 | AD13: =_xlfn.PERCENTILE.INC($E$2:$E$231,0.75) -> 201189.25
B14: TJX | C14: United States | D14: Retail | E14: 364000 | F14: {=_xlfn.IFS( E14<=$E$245,0, E14<=$E$246,1, E14<=$E$247,2, E14>=$E$247,3)} -> 3 | G14: {=_xlfn.IFS( OR(D14="Aerospace",D14="Aerospace & Defense",D14="Agricultural Equipment",D14="Airlines",D14="Automotive",D14="Automotive & Energy",D14="Automotive Components",D14="Aviation",D14="Building Materials",D14="Chemicals",D14="Commercial Vehicles",D14="Conglomerate & Defense",D14="Conglomerate & Energy",D14="Construction",D14="Construction & Infrastructure",D14="Construction & Real Estate",D14="Construction & Telecom",D14="Discount Retail",D14="Energy Management",D14="Energy Technology",D14="Engines & Power Systems",D14="Environmental Services",D14="Food Distribution",D14="Food Services",D14="Grocery Retail",D14="Healthcare & Pharmacy",D14="Home Improvement Retail",D14="Industrial Engineering & Electronics",D14="Oilfield Services",D14="Pharmaceuticals",D14="Pharmaceuticals & Chemicals",D14="Pharmaceuticals & Healthcare",D14="Pharmacy Retail",D14="Postal & Logistics",D14="Retail",D14="Retail & Distribution",D14="Retail & Grocery",D14="Retail (IKEA)",D14="Tobacco",D14="Trading & Conglomerate",D14="Utilities",D14="Utilities & Energy",D14="Wholesale Retail"),2, OR(D14="Agribusiness",D14="Automotive & Heavy Vehicles",D14="Chemicals",D14="Commercial Vehicles",D14="Construction",D14="Construction & Infrastructure",D14="Engines & Power Systems",D14="Food Processing",D14="Healthcare",D14="Healthcare & Medical Devices",D14="Heavy Equipment",D14="Heavy Industry",D14="Industrial Gases",D14="Industrial Manufacturing",D14="Logistics",D14="Medical Devices",D14="Mining",D14="Mining & Commodities Trading",D14="Oil & Gas",D14="Oilfield Services",D14="Rail Transport",D14="Shipping & Logistics",D14="Steel"),3, OR(D14="Apparel & Footwear",D14="Beverage",D14="Coffeehouse & Retail",D14="Conglomerate",D14="Consumer Goods",D14="Convenience Retail",D14="Electronics",D14="Electronics & Semiconductors",D14="Electronics Retail",D14="Fashion Retail",D14="Food & Beverage",D14="Food Retail & Consumer Goods",D14="Industrial & Technology",D14="Industrial Automation",D14="Industrial Technology",D14="Postal & Financial Services",D14="Postal Services",D14="Scientific Instruments",D14="Technology Hardware",D14="Trading Company",D14="IT Consulting"),1, OR(D14="Cosmetics",D14="E-commerce & Cloud Computing",D14="Electronics & Entertainment",D14="Entertainment & Media",D14="Luxury Goods",D14="Media & Telecommunications",D14="Networking Technology",D14="Real Estate Services",D14="Technology & Consumer Electronics",D14="Telecommunications",D14="Telecommunications & Investment"),1, OR(D14="Asset Management",D14="Banking",D14="Banking & Asset Services",D14="Banking & Financial Services",D14="Banking & Wealth Management",D14="Cloud Software",D14="Enterprise Software",D14="Financial Services",D14="Information Technology Consulting",D14="Investment Banking",D14="Social Media & Technology",D14="Software & Cloud Computing",D14="Technology & Consulting",D14="Technology & Internet Services",D14="Technology & Software"),1, TRUE,"Unmapped" )} -> 2 | H14: 1 | I14: =VLOOKUP(B14,'BIS + EDBA Final'!A:F,6,FALSE) -> 1 | J14: =VLOOKUP(B14,'CBG Final'!A:B,2,FALSE) -> 3 | K14: =0.3*F14+0.2*G14+0.2*H14+I14*0.1+J14*0.2 -> 2.2 | L14: 56,360 | M14: 4% | N14: 4,864 | O14: 8.7% | P14: 31,749 | Q14: 14 | R14: 24
B15: PepsiCo | C15: United States | D15: Food & Beverage | E15: 319000 | F15: {=_xlfn.IFS( E15<=$E$245,0, E15<=$E$246,1, E15<=$E$247,2, E15>=$E$247,3)} -> 3 | G15: {=_xlfn.IFS( OR(D15="Aerospace",D15="Aerospace & Defense",D15="Agricultural Equipment",D15="Airlines",D15="Automotive",D15="Automotive & Energy",D15="Automotive Components",D15="Aviation",D15="Building Materials",D15="Chemicals",D15="Commercial Vehicles",D15="Conglomerate & Defense",D15="Conglomerate & Energy",D15="Construction",D15="Construction & Infrastructure",D15="Construction & Real Estate",D15="Construction & Telecom",D15="Discount Retail",D15="Energy Management",D15="Energy Technology",D15="Engines & Power Systems",D15="Environmental Services",D15="Food Distribution",D15="Food Services",D15="Grocery Retail",D15="Healthcare & Pharmacy",D15="Home Improvement Retail",D15="Industrial Engineering & Electronics",D15="Oilfield Services",D15="Pharmaceuticals",D15="Pharmaceuticals & Chemicals",D15="Pharmaceuticals & Healthcare",D15="Pharmacy Retail",D15="Postal & Logistics",D15="Retail",D15="Retail & Distribution",D15="Retail & Grocery",D15="Retail (IKEA)",D15="Tobacco",D15="Trading & Conglomerate",D15="Utilities",D15="Utilities & Energy",D15="Wholesale Retail"),2, OR(D15="Agribusiness",D15="Automotive & Heavy Vehicles",D15="Chemicals",D15="Commercial Vehicles",D15="Construction",D15="Construction & Infrastructure",D15="Engines & Power Systems",D15="Food Processing",D15="Healthcare",D15="Healthcare & Medical Devices",D15="Heavy Equipment",D15="Heavy Industry",D15="Industrial Gases",D15="Industrial Manufacturing",D15="Logistics",D15="Medical Devices",D15="Mining",D15="Mining & Commodities Trading",D15="Oil & Gas",D15="Oilfield Services",D15="Rail Transport",D15="Shipping & Logistics",D15="Steel"),3, OR(D15="Apparel & Footwear",D15="Beverage",D15="Coffeehouse & Retail",D15="Conglomerate",D15="Consumer Goods",D15="Convenience Retail",D15="Electronics",D15="Electronics & Semiconductors",D15="Electronics Retail",D15="Fashion Retail",D15="Food & Beverage",D15="Food Retail & Consumer Goods",D15="Industrial & Technology",D15="Industrial Automation",D15="Industrial Technology",D15="Postal & Financial Services",D15="Postal Services",D15="Scientific Instruments",D15="Technology Hardware",D15="Trading Company",D15="IT Consulting"),1, OR(D15="Cosmetics",D15="E-commerce & Cloud Computing",D15="Electronics & Entertainment",D15="Entertainment & Media",D15="Luxury Goods",D15="Media & Telecommunications",D15="Networking Technology",D15="Real Estate Services",D15="Technology & Consumer Electronics",D15="Telecommunications",D15="Telecommunications & Investment"),1, OR(D15="Asset Management",D15="Banking",D15="Banking & Asset Services",D15="Banking & Financial Services",D15="Banking & Wealth Management",D15="Cloud Software",D15="Enterprise Software",D15="Financial Services",D15="Information Technology Consulting",D15="Investment Banking",D15="Social Media & Technology",D15="Software & Cloud Computing",D15="Technology & Consulting",D15="Technology & Internet Services",D15="Technology & Software"),1, TRUE,"Unmapped" )} -> 1 | H15: 2 | I15: =VLOOKUP(B15,'BIS + EDBA Final'!A:F,6,FALSE) -> 1 | J15: =VLOOKUP(B15,'CBG Final'!A:B,2,FALSE) -> 3 | K15: =0.3*F15+0.2*G15+0.2*H15+I15*0.1+J15*0.2 -> 2.2 | L15: 91,854 | M15: 0.4% | N15: 9,578 | O15: 5.6% | P15: 99,467 | Q15: 8 | R15: 31
B16: Walt Disney | C16: United States | D16: Entertainment & Media | E16: 205040 | F16: {=_xlfn.IFS( E16<=$E$245,0, E16<=$E$246,1, E16<=$E$247,2, E16>=$E$247,3)} -> 3 | G16: {=_xlfn.IFS( OR(D16="Aerospace",D16="Aerospace & Defense",D16="Agricultural Equipment",D16="Airlines",D16="Automotive",D16="Automotive & Energy",D16="Automotive Components",D16="Aviation",D16="Building Materials",D16="Chemicals",D16="Commercial Vehicles",D16="Conglomerate & Defense",D16="Conglomerate & Energy",D16="Construction",D16="Construction & Infrastructure",D16="Construction & Real Estate",D16="Construction & Telecom",D16="Discount Retail",D16="Energy Management",D16="Energy Technology",D16="Engines & Power Systems",D16="Environmental Services",D16="Food Distribution",D16="Food Services",D16="Grocery Retail",D16="Healthcare & Pharmacy",D16="Home Improvement Retail",D16="Industrial Engineering & Electronics",D16="Oilfield Services",D16="Pharmaceuticals",D16="Pharmaceuticals & Chemicals",D16="Pharmaceuticals & Healthcare",D16="Pharmacy Retail",D16="Postal & Logistics",D16="Retail",D16="Retail & Distribution",D16="Retail & Grocery",D16="Retail (IKEA)",D16="Tobacco",D16="Trading & Conglomerate",D16="Utilities",D16="Utilities & Energy",D16="Wholesale Retail"),2, OR(D16="Agribusiness",D16="Automotive & Heavy Vehicles",D16="Chemicals",D16="Commercial Vehicles",D16="Construction",D16="Construction & Infrastructure",D16="Engines & Power Systems",D16="Food Processing",D16="Healthcare",D16="Healthcare & Medical Devices",D16="Heavy Equipment",D16="Heavy Industry",D16="Industrial Gases",D16="Industrial Manufacturing",D16="Logistics",D16="Medical Devices",D16="Mining",D16="Mining & Commodities Trading",D16="Oil & Gas",D16="Oilfield Services",D16="Rail Transport",D16="Shipping & Logistics",D16="Steel"),3, OR(D16="Apparel & Footwear",D16="Beverage",D16="Coffeehouse & Retail",D16="Conglomerate",D16="Consumer Goods",D16="Convenience Retail",D16="Electronics",D16="Electronics & Semiconductors",D16="Electronics Retail",D16="Fashion Retail",D16="Food & Beverage",D16="Food Retail & Consumer Goods",D16="Industrial & Technology",D16="Industrial Automation",D16="Industrial Technology",D16="Postal & Financial Services",D16="Postal Services",D16="Scientific Instruments",D16="Technology Hardware",D16="Trading Company",D16="IT Consulting"),1, OR(D16="Cosmetics",D16="E-commerce & Cloud Computing",D16="Electronics & Entertainment",D16="Entertainment & Media",D16="Luxury Goods",D16="Media & Telecommunications",D16="Networking Technology",D16="Real Estate Services",D16="Technology & Consumer Electronics",D16="Telecommunications",D16="Telecommunications & Investment"),1, OR(D16="Asset Management",D16="Banking",D16="Banking & Asset Services",D16="Banking & Financial Services",D16="Banking & Wealth Management",D16="Cloud Software",D16="Enterprise Software",D16="Financial Services",D16="Information Technology Consulting",D16="Investment Banking",D16="Social Media & Technology",D16="Software & Cloud Computing",D16="Technology & Consulting",D16="Technology & Internet Services",D16="Technology & Software"),1, TRUE,"Unmapped" )} -> 1 | H16: 2 | I16: =VLOOKUP(B16,'BIS + EDBA Final'!A:F,6,FALSE) -> 1 | J16: =VLOOKUP(B16,'CBG Final'!A:B,2,FALSE) -> 3 | K16: =0.3*F16+0.2*G16+0.2*H16+I16*0.1+J16*0.2 -> 2.2 | L16: 91,361 | M16: 2.8% | N16: 4,972 | O16: 111.2% | P16: 196,219 | Q16: 9 | R16: 31
B17: Citigroup | C17: United States | D17: Banking | E17: 227855 | F17: {=_xlfn.IFS( E17<=$E$245,0, E17<=$E$246,1, E17<=$E$247,2, E17>=$E$247,3)} -> 3 | G17: {=_xlfn.IFS( OR(D17="Aerospace",D17="Aerospace & Defense",D17="Agricultural Equipment",D17="Airlines",D17="Automotive",D17="Automotive & Energy",D17="Automotive Components",D17="Aviation",D17="Building Materials",D17="Chemicals",D17="Commercial Vehicles",D17="Conglomerate & Defense",D17="Conglomerate & Energy",D17="Construction",D17="Construction & Infrastructure",D17="Construction & Real Estate",D17="Construction & Telecom",D17="Discount Retail",D17="Energy Management",D17="Energy Technology",D17="Engines & Power Systems",D17="Environmental Services",D17="Food Distribution",D17="Food Services",D17="Grocery Retail",D17="Healthcare & Pharmacy",D17="Home Improvement Retail",D17="Industrial Engineering & Electronics",D17="Oilfield Services",D17="Pharmaceuticals",D17="Pharmaceuticals & Chemicals",D17="Pharmaceuticals & Healthcare",D17="Pharmacy Retail",D17="Postal & Logistics",D17="Retail",D17="Retail & Distribution",D17="Retail & Grocery",D17="Retail (IKEA)",D17="Tobacco",D17="Trading & Conglomerate",D17="Utilities",D17="Utilities & Energy",D17="Wholesale Retail"),2, OR(D17="Agribusiness",D17="Automotive & Heavy Vehicles",D17="Chemicals",D17="Commercial Vehicles",D17="Construction",D17="Construction & Infrastructure",D17="Engines & Power Systems",D17="Food Processing",D17="Healthcare",D17="Healthcare & Medical Devices",D17="Heavy Equipment",D17="Heavy Industry",D17="Industrial Gases",D17="Industrial Manufacturing",D17="Logistics",D17="Medical Devices",D17="Mining",D17="Mining & Commodities Trading",D17="Oil & Gas",D17="Oilfield Services",D17="Rail Transport",D17="Shipping & Logistics",D17="Steel"),3, OR(D17="Apparel & Footwear",D17="Beverage",D17="Coffeehouse & Retail",D17="Conglomerate",D17="Consumer Goods",D17="Convenience Retail",D17="Electronics",D17="Electronics & Semiconductors",D17="Electronics Retail",D17="Fashion Retail",D17="Food & Beverage",D17="Food Retail & Consumer Goods",D17="Industrial & Technology",D17="Industrial Automation",D17="Industrial Technology",D17="Postal & Financial Services",D17="Postal Services",D17="Scientific Instruments",D17="Technology Hardware",D17="Trading Company",D17="IT Consulting"),1, OR(D17="Cosmetics",D17="E-commerce & Cloud Computing",D17="Electronics & Entertainment",D17="Entertainment & Media",D17="Luxury Goods",D17="Media & Telecommunications",D17="Networking Technology",D17="Real Estate Services",D17="Technology & Consumer Electronics",D17="Telecommunications",D17="Telecommunications & Investment"),1, OR(D17="Asset Management",D17="Banking",D17="Banking & Asset Services",D17="Banking & Financial Services",D17="Banking & Wealth Management",D17="Cloud Software",D17="Enterprise Software",D17="Financial Services",D17="Information Technology Consulting",D17="Investment Banking",D17="Social Media & Technology",D17="Software & Cloud Computing",D17="Technology & Consulting",D17="Technology & Internet Services",D17="Technology & Software"),1, TRUE,"Unmapped" )} -> 1 | H17: 2 | I17: =VLOOKUP(B17,'BIS + EDBA Final'!A:F,6,FALSE) -> 1 | J17: =VLOOKUP(B17,'CBG Final'!A:B,2,FALSE) -> 3 | K17: =0.3*F17+0.2*G17+0.2*H17+I17*0.1+J17*0.2 -> 2.2 | L17: 170,757 | M17: 8.9% | N17: 12,682 | O17: 37.4% | P17: 2,352,945 | Q17: 6 | R17: 31
B18: Microsoft | C18: United States | D18: Technology & Software | E18: 228000 | F18: {=_xlfn.IFS( E18<=$E$245,0, E18<=$E$246,1, E18<=$E$247,2, E18>=$E$247,3)} -> 3 | G18: {=_xlfn.IFS( OR(D18="Aerospace",D18="Aerospace & Defense",D18="Agricultural Equipment",D18="Airlines",D18="Automotive",D18="Automotive & Energy",D18="Automotive Components",D18="Aviation",D18="Building Materials",D18="Chemicals",D18="Commercial Vehicles",D18="Conglomerate & Defense",D18="Conglomerate & Energy",D18="Construction",D18="Construction & Infrastructure",D18="Construction & Real Estate",D18="Construction & Telecom",D18="Discount Retail",D18="Energy Management",D18="Energy Technology",D18="Engines & Power Systems",D18="Environmental Services",D18="Food Distribution",D18="Food Services",D18="Grocery Retail",D18="Healthcare & Pharmacy",D18="Home Improvement Retail",D18="Industrial Engineering & Electronics",D18="Oilfield Services",D18="Pharmaceuticals",D18="Pharmaceuticals & Chemicals",D18="Pharmaceuticals & Healthcare",D18="Pharmacy Retail",D18="Postal & Logistics",D18="Retail",D18="Retail & Distribution",D18="Retail & Grocery",D18="Retail (IKEA)",D18="Tobacco",D18="Trading & Conglomerate",D18="Utilities",D18="Utilities & Energy",D18="Wholesale Retail"),2, OR(D18="Agribusiness",D18="Automotive & Heavy Vehicles",D18="Chemicals",D18="Commercial Vehicles",D18="Construction",D18="Construction & Infrastructure",D18="Engines & Power Systems",D18="Food Processing",D18="Healthcare",D18="Healthcare & Medical Devices",D18="Heavy Equipment",D18="Heavy Industry",D18="Industrial Gases",D18="Industrial Manufacturing",D18="Logistics",D18="Medical Devices",D18="Mining",D18="Mining & Commodities Trading",D18="Oil & Gas",D18="Oilfield Services",D18="Rail Transport",D18="Shipping & Logistics",D18="Steel"),3, OR(D18="Apparel & Footwear",D18="Beverage",D18="Coffeehouse & Retail",D18="Conglomerate",D18="Consumer Goods",D18="Convenience Retail",D18="Electronics",D18="Electronics & Semiconductors",D18="Electronics Retail",D18="Fashion Retail",D18="Food & Beverage",D18="Food Retail & Consumer Goods",D18="Industrial & Technology",D18="Industrial Automation",D18="Industrial Technology",D18="Postal & Financial Services",D18="Postal Services",D18="Scientific Instruments",D18="Technology Hardware",D18="Trading Company",D18="IT Consulting"),1, OR(D18="Cosmetics",D18="E-commerce & Cloud Computing",D18="Electronics & Entertainment",D18="Entertainment & Media",D18="Luxury Goods",D18="Media & Telecommunications",D18="Networking Technology",D18="Real Estate Services",D18="Technology & Consumer Electronics",D18="Telecommunications",D18="Telecommunications & Investment"),1, OR(D18="Asset Management",D18="Banking",D18="Banking & Asset Services",D18="Banking & Financial Services",D18="Banking & Wealth Management",D18="Cloud Software",D18="Enterprise Software",D18="Financial Services",D18="Information Technology Consulting",D18="Investment Banking",D18="Social Media & Technology",D18="Software & Cloud Computing",D18="Technology & Consulting",D18="Technology & Internet Services",D18="Technology & Software"),1, TRUE,"Unmapped" )} -> 1 | H18: 3 | I18: =VLOOKUP(B18,'BIS + EDBA Final'!A:F,6,FALSE) -> -1 | J18: =VLOOKUP(B18,'CBG Final'!A:B,2,FALSE) -> 3 | K18: =0.3*F18+0.2*G18+0.2*H18+I18*0.1+J18*0.2 -> 2.2 | L18: 245,122 | M18: 15.7% | N18: 88,136 | O18: 21.8% | P18: 512,163 | Q18: 4 | R18: 28
